Collecting poetry==1.2.0
  Downloading poetry-1.2.0-py3-none-any.whl (210 kB)
     ━━━━━━━━━━━━━━━━━━━━━━━━━╸             143.4/210.9 kB 53.9 kB/s eta 0:00:02
ERROR: Exception:
Traceback (most recent call last):
  File "/Users/I549061/Library/Application Support/pypoetry/venv/lib/python3.9/site-packages/pip/_vendor/urllib3/response.py", line 435, in _error_catcher
    yield
  File "/Users/I549061/Library/Application Support/pypoetry/venv/lib/python3.9/site-packages/pip/_vendor/urllib3/response.py", line 516, in read
    data = self._fp.read(amt) if not fp_closed else b""
  File "/Users/I549061/Library/Application Support/pypoetry/venv/lib/python3.9/site-packages/pip/_vendor/cachecontrol/filewrapper.py", line 90, in read
    data = self.__fp.read(amt)
  File "/usr/local/Cellar/python@3.9/3.9.12_1/Frameworks/Python.framework/Versions/3.9/lib/python3.9/http/client.py", line 463, in read
    n = self.readinto(b)
  File "/usr/local/Cellar/python@3.9/3.9.12_1/Frameworks/Python.framework/Versions/3.9/lib/python3.9/http/client.py", line 507, in readinto
    n = self.fp.readinto(b)
  File "/usr/local/Cellar/python@3.9/3.9.12_1/Frameworks/Python.framework/Versions/3.9/lib/python3.9/socket.py", line 704, in readinto
    return self._sock.recv_into(b)
  File "/usr/local/Cellar/python@3.9/3.9.12_1/Frameworks/Python.framework/Versions/3.9/lib/python3.9/ssl.py", line 1241, in recv_into
    return self.read(nbytes, buffer)
  File "/usr/local/Cellar/python@3.9/3.9.12_1/Frameworks/Python.framework/Versions/3.9/lib/python3.9/ssl.py", line 1099, in read
    return self._sslobj.read(len, buffer)
socket.timeout: The read operation timed out

During handling of the above exception, another exception occurred:

Traceback (most recent call last):
  File "/Users/I549061/Library/Application Support/pypoetry/venv/lib/python3.9/site-packages/pip/_internal/cli/base_command.py", line 167, in exc_logging_wrapper
    status = run_func(*args)
  File "/Users/I549061/Library/Application Support/pypoetry/venv/lib/python3.9/site-packages/pip/_internal/cli/req_command.py", line 247, in wrapper
    return func(self, options, args)
  File "/Users/I549061/Library/Application Support/pypoetry/venv/lib/python3.9/site-packages/pip/_internal/commands/install.py", line 369, in run
    requirement_set = resolver.resolve(
  File "/Users/I549061/Library/Application Support/pypoetry/venv/lib/python3.9/site-packages/pip/_internal/resolution/resolvelib/resolver.py", line 92, in resolve
    result = self._result = resolver.resolve(
  File "/Users/I549061/Library/Application Support/pypoetry/venv/lib/python3.9/site-packages/pip/_vendor/resolvelib/resolvers.py", line 481, in resolve
    state = resolution.resolve(requirements, max_rounds=max_rounds)
  File "/Users/I549061/Library/Application Support/pypoetry/venv/lib/python3.9/site-packages/pip/_vendor/resolvelib/resolvers.py", line 348, in resolve
    self._add_to_criteria(self.state.criteria, r, parent=None)
  File "/Users/I549061/Library/Application Support/pypoetry/venv/lib/python3.9/site-packages/pip/_vendor/resolvelib/resolvers.py", line 172, in _add_to_criteria
    if not criterion.candidates:
  File "/Users/I549061/Library/Application Support/pypoetry/venv/lib/python3.9/site-packages/pip/_vendor/resolvelib/structs.py", line 151, in __bool__
    return bool(self._sequence)
  File "/Users/I549061/Library/Application Support/pypoetry/venv/lib/python3.9/site-packages/pip/_internal/resolution/resolvelib/found_candidates.py", line 155, in __bool__
    return any(self)
  File "/Users/I549061/Library/Application Support/pypoetry/venv/lib/python3.9/site-packages/pip/_internal/resolution/resolvelib/found_candidates.py", line 143, in <genexpr>
    return (c for c in iterator if id(c) not in self._incompatible_ids)
  File "/Users/I549061/Library/Application Support/pypoetry/venv/lib/python3.9/site-packages/pip/_internal/resolution/resolvelib/found_candidates.py", line 47, in _iter_built
    candidate = func()
  File "/Users/I549061/Library/Application Support/pypoetry/venv/lib/python3.9/site-packages/pip/_internal/resolution/resolvelib/factory.py", line 206, in _make_candidate_from_link
    self._link_candidate_cache[link] = LinkCandidate(
  File "/Users/I549061/Library/Application Support/pypoetry/venv/lib/python3.9/site-packages/pip/_internal/resolution/resolvelib/candidates.py", line 297, in __init__
    super().__init__(
  File "/Users/I549061/Library/Application Support/pypoetry/venv/lib/python3.9/site-packages/pip/_internal/resolution/resolvelib/candidates.py", line 162, in __init__
    self.dist = self._prepare()
  File "/Users/I549061/Library/Application Support/pypoetry/venv/lib/python3.9/site-packages/pip/_internal/resolution/resolvelib/candidates.py", line 231, in _prepare
    dist = self._prepare_distribution()
  File "/Users/I549061/Library/Application Support/pypoetry/venv/lib/python3.9/site-packages/pip/_internal/resolution/resolvelib/candidates.py", line 308, in _prepare_distribution
    return preparer.prepare_linked_requirement(self._ireq, parallel_builds=True)
  File "/Users/I549061/Library/Application Support/pypoetry/venv/lib/python3.9/site-packages/pip/_internal/operations/prepare.py", line 438, in prepare_linked_requirement
    return self._prepare_linked_requirement(req, parallel_builds)
  File "/Users/I549061/Library/Application Support/pypoetry/venv/lib/python3.9/site-packages/pip/_internal/operations/prepare.py", line 483, in _prepare_linked_requirement
    local_file = unpack_url(
  File "/Users/I549061/Library/Application Support/pypoetry/venv/lib/python3.9/site-packages/pip/_internal/operations/prepare.py", line 165, in unpack_url
    file = get_http_url(
  File "/Users/I549061/Library/Application Support/pypoetry/venv/lib/python3.9/site-packages/pip/_internal/operations/prepare.py", line 106, in get_http_url
    from_path, content_type = download(link, temp_dir.path)
  File "/Users/I549061/Library/Application Support/pypoetry/venv/lib/python3.9/site-packages/pip/_internal/network/download.py", line 147, in __call__
    for chunk in chunks:
  File "/Users/I549061/Library/Application Support/pypoetry/venv/lib/python3.9/site-packages/pip/_internal/cli/progress_bars.py", line 53, in _rich_progress_bar
    for chunk in iterable:
  File "/Users/I549061/Library/Application Support/pypoetry/venv/lib/python3.9/site-packages/pip/_internal/network/utils.py", line 63, in response_chunks
    for chunk in response.raw.stream(
  File "/Users/I549061/Library/Application Support/pypoetry/venv/lib/python3.9/site-packages/pip/_vendor/urllib3/response.py", line 573, in stream
    data = self.read(amt=amt, decode_content=decode_content)
  File "/Users/I549061/Library/Application Support/pypoetry/venv/lib/python3.9/site-packages/pip/_vendor/urllib3/response.py", line 538, in read
    raise IncompleteRead(self._fp_bytes_read, self.length_remaining)
  File "/usr/local/Cellar/python@3.9/3.9.12_1/Frameworks/Python.framework/Versions/3.9/lib/python3.9/contextlib.py", line 137, in __exit__
    self.gen.throw(typ, value, traceback)
  File "/Users/I549061/Library/Application Support/pypoetry/venv/lib/python3.9/site-packages/pip/_vendor/urllib3/response.py", line 440, in _error_catcher
    raise ReadTimeoutError(self._pool, None, "Read timed out.")
pip._vendor.urllib3.exceptions.ReadTimeoutError: HTTPSConnectionPool(host='files.pythonhosted.org', port=443): Read timed out.
WARNING: There was an error checking the latest version of pip.

Traceback:

  File "<stdin>", line 914, in main
  File "<stdin>", line 545, in run
  File "<stdin>", line 567, in install
  File "<stdin>", line 670, in install_poetry
  File "<stdin>", line 362, in pip
  File "<stdin>", line 359, in python
  File "<stdin>", line 352, in run
